{"trial_id": "01", "hyperparameters": {"space": [{"class_name": "Int", "config": {"name": "units", "default": null, "conditions": [], "min_value": 32, "max_value": 512, "step": 32, "sampling": "linear"}}, {"class_name": "Float", "config": {"name": "dropout", "default": 0.25, "conditions": [], "min_value": 0.0, "max_value": 0.5, "step": 0.05, "sampling": "linear"}}, {"class_name": "Float", "config": {"name": "learning_rate", "default": 0.0001, "conditions": [], "min_value": 0.0001, "max_value": 0.01, "step": null, "sampling": "log"}}], "values": {"units": 320, "dropout": 0.15000000000000002, "learning_rate": 0.000575732702957742}}, "metrics": {"metrics": {}}, "score": null, "best_step": 0, "status": "FAILED", "message": "Traceback (most recent call last):\n  File \"/Library/Frameworks/Python.framework/Versions/3.11/lib/python3.11/site-packages/keras_tuner/src/engine/base_tuner.py\", line 273, in _try_run_and_update_trial\n    self._run_and_update_trial(trial, *fit_args, **fit_kwargs)\n  File \"/Library/Frameworks/Python.framework/Versions/3.11/lib/python3.11/site-packages/keras_tuner/src/engine/base_tuner.py\", line 238, in _run_and_update_trial\n    results = self.run_trial(trial, *fit_args, **fit_kwargs)\n              ^^^^^^^^^^^^^^^^^^^^^^^^^^^^^^^^^^^^^^^^^^^^^^\n  File \"/Library/Frameworks/Python.framework/Versions/3.11/lib/python3.11/site-packages/keras_tuner/src/engine/tuner.py\", line 314, in run_trial\n    obj_value = self._build_and_fit_model(trial, *args, **copied_kwargs)\n                ^^^^^^^^^^^^^^^^^^^^^^^^^^^^^^^^^^^^^^^^^^^^^^^^^^^^^^^^\n  File \"/Library/Frameworks/Python.framework/Versions/3.11/lib/python3.11/site-packages/keras_tuner/src/engine/tuner.py\", line 233, in _build_and_fit_model\n    results = self.hypermodel.fit(hp, model, *args, **kwargs)\n              ^^^^^^^^^^^^^^^^^^^^^^^^^^^^^^^^^^^^^^^^^^^^^^^\n  File \"/Library/Frameworks/Python.framework/Versions/3.11/lib/python3.11/site-packages/keras_tuner/src/engine/hypermodel.py\", line 149, in fit\n    return model.fit(*args, **kwargs)\n           ^^^^^^^^^^^^^^^^^^^^^^^^^^\n  File \"/Library/Frameworks/Python.framework/Versions/3.11/lib/python3.11/site-packages/keras/src/utils/traceback_utils.py\", line 70, in error_handler\n    raise e.with_traceback(filtered_tb) from None\n  File \"/var/folders/94/903y39c95x3g49g0_7l22jn00000gn/T/__autograph_generated_file4dx0gk5f.py\", line 18, in tf__train_function\n    raise\nValueError: in user code:\n\n    File \"/Library/Frameworks/Python.framework/Versions/3.11/lib/python3.11/site-packages/keras/src/engine/training.py\", line 1401, in train_function  *\n        return step_function(self, iterator)\n    File \"/Library/Frameworks/Python.framework/Versions/3.11/lib/python3.11/site-packages/keras/src/engine/training.py\", line 1384, in step_function  **\n        outputs = model.distribute_strategy.run(run_step, args=(data,))\n    File \"/Library/Frameworks/Python.framework/Versions/3.11/lib/python3.11/site-packages/keras/src/engine/training.py\", line 1373, in run_step  **\n        outputs = model.train_step(data)\n    File \"/Library/Frameworks/Python.framework/Versions/3.11/lib/python3.11/site-packages/keras/src/engine/training.py\", line 1151, in train_step\n        loss = self.compute_loss(x, y, y_pred, sample_weight)\n    File \"/Library/Frameworks/Python.framework/Versions/3.11/lib/python3.11/site-packages/keras/src/engine/training.py\", line 1209, in compute_loss\n        return self.compiled_loss(\n    File \"/Library/Frameworks/Python.framework/Versions/3.11/lib/python3.11/site-packages/keras/src/engine/compile_utils.py\", line 277, in __call__\n        loss_value = loss_obj(y_t, y_p, sample_weight=sw)\n    File \"/Library/Frameworks/Python.framework/Versions/3.11/lib/python3.11/site-packages/keras/src/losses.py\", line 143, in __call__\n        losses = call_fn(y_true, y_pred)\n    File \"/Library/Frameworks/Python.framework/Versions/3.11/lib/python3.11/site-packages/keras/src/losses.py\", line 270, in call  **\n        return ag_fn(y_true, y_pred, **self._fn_kwargs)\n    File \"/Library/Frameworks/Python.framework/Versions/3.11/lib/python3.11/site-packages/keras/src/losses.py\", line 2532, in binary_crossentropy\n        backend.binary_crossentropy(y_true, y_pred, from_logits=from_logits),\n    File \"/Library/Frameworks/Python.framework/Versions/3.11/lib/python3.11/site-packages/keras/src/backend.py\", line 5822, in binary_crossentropy\n        return tf.nn.sigmoid_cross_entropy_with_logits(\n\n    ValueError: `logits` and `labels` must have the same shape, received ((None, 2) vs (None, 60, 2)).\n\n"}